<?xml version="1.0" ?>
<sdf version="1.9">
    
    <model name='x500_base'>
      <pose>4.28082 8.57073 0.24 0 -0 0</pose>
      <self_collide>false</self_collide>
      <static>false</static>
      <link name='base_link'>
        <inertial>
          <mass>2</mass>
          <inertia>
            <ixx>0.021666700000000001</ixx>
            <ixy>0</ixy>
            <ixz>0</ixz>
            <iyy>0.021666700000000001</iyy>
            <iyz>0</iyz>
            <izz>0.040000000000000001</izz>
          </inertia>
          <pose>0 0 0 0 -0 0</pose>
        </inertial>
        <gravity>true</gravity>
        <velocity_decay/>
        <visual name='base_link_visual'>
          <pose>0 0 .025 0 0 3.141592654</pose>
          <geometry>
            <mesh>
              <scale>1 1 1</scale>
              <uri>https://fuel.gazebosim.org/1.0/px4/models/x500_base/1/files/meshes/NXP-HGD-CF.dae</uri>
            </mesh>
          </geometry>
        </visual>
        <visual name='5010_motor_base_0'>
          <pose>0.174 0.174 .032 0 0 -.45</pose>
          <geometry>
            <mesh>
              <scale>1 1 1</scale>
              <uri>https://fuel.gazebosim.org/1.0/px4/models/x500_base/1/files/meshes/5010Base.dae</uri>
            </mesh>
          </geometry>
        </visual>
        <visual name='5010_motor_base_1'>
          <pose>-0.174 0.174 .032 0 0 -.45</pose>
          <geometry>
            <mesh>
              <scale>1 1 1</scale>
              <uri>https://fuel.gazebosim.org/1.0/px4/models/x500_base/1/files/meshes/5010Base.dae</uri>
            </mesh>
          </geometry>
        </visual>
        <visual name='5010_motor_base_2'>
          <pose>0.174 -0.174 .032 0 0 -.45</pose>
          <geometry>
            <mesh>
              <scale>1 1 1</scale>
              <uri>https://fuel.gazebosim.org/1.0/px4/models/x500_base/1/files/meshes/5010Base.dae</uri>
            </mesh>
          </geometry>
        </visual>
        <visual name='5010_motor_base_3'>
          <pose>-0.174 -0.174 .032 0 0 -.45</pose>
          <geometry>
            <mesh>
              <scale>1 1 1</scale>
              <uri>https://fuel.gazebosim.org/1.0/px4/models/x500_base/1/files/meshes/5010Base.dae</uri>
            </mesh>
          </geometry>
        </visual>
        <visual name='NXP_FMUK66_FRONT'>
          <pose>0.047 .001 .043 1 0 1.57</pose>
          <cast_shadows>false</cast_shadows>
          <geometry>
            <plane>
              <normal>0 0 1</normal>
              <size>0.013 0.007</size>
            </plane>
          </geometry>
          <material>
            <diffuse>1 1 1 1</diffuse>
            <specular>1 1 1 1</specular>
            <pbr>
              <metal>
                <albedo_map>https://fuel.gazebosim.org/1.0/px4/models/x500_base/1/files/materials/textures/nxp.png</albedo_map>
              </metal>
            </pbr>
          </material>
        </visual>
        <visual name='NXP_FMUK66_TOP'>
          <pose>-0.023 0 .0515 0 0 -1.57</pose>
          <cast_shadows>false</cast_shadows>
          <geometry>
            <plane>
              <normal>0 0 1</normal>
              <size>0.013 0.007</size>
            </plane>
          </geometry>
          <material>
            <diffuse>1 1 1 1</diffuse>
            <specular>1 1 1 1</specular>
            <pbr>
              <metal>
                <albedo_map>https://fuel.gazebosim.org/1.0/px4/models/x500_base/1/files/materials/textures/nxp.png</albedo_map>
              </metal>
            </pbr>
          </material>
        </visual>
        <visual name='RDDRONE_FMUK66_TOP'>
          <pose>-.03 0 .0515 0 0 -1.57</pose>
          <cast_shadows>false</cast_shadows>
          <geometry>
            <plane>
              <normal>0 0 1</normal>
              <size>0.032 0.0034</size>
            </plane>
          </geometry>
          <material>
            <diffuse>1 1 1 1</diffuse>
            <specular>1 1 1 1</specular>
            <pbr>
              <metal>
                <albedo_map>https://fuel.gazebosim.org/1.0/px4/models/x500_base/1/files/materials/textures/rd.png</albedo_map>
              </metal>
            </pbr>
          </material>
        </visual>
        <collision name='base_link_collision_0'>
          <pose>0 0 .007 0 0 0</pose>
          <geometry>
            <box>
              <size>0.353553 0.353553 0.05</size>
            </box>
          </geometry>
          <surface>
            <contact>
              <ode>
                <min_depth>0.001</min_depth>
                <max_vel>0</max_vel>
              </ode>
            </contact>
            <friction>
              <ode/>
            </friction>
            <bounce/>
          </surface>
        </collision>
        <collision name='base_link_collision_1'>
          <pose>0 -0.098 -.123 -0.35 0 0</pose>
          <geometry>
            <box>
              <size>0.015 0.015 0.21</size>
            </box>
          </geometry>
          <surface>
            <contact>
              <ode>
                <min_depth>0.001</min_depth>
                <max_vel>0</max_vel>
              </ode>
            </contact>
            <friction>
              <ode/>
            </friction>
            <bounce/>
          </surface>
        </collision>
        <collision name='base_link_collision_2'>
          <pose>0 0.098 -.123 0.35 0 0</pose>
          <geometry>
            <box>
              <size>0.015 0.015 0.21</size>
            </box>
          </geometry>
          <surface>
            <contact>
              <ode>
                <min_depth>0.001</min_depth>
                <max_vel>0</max_vel>
              </ode>
            </contact>
            <friction>
              <ode/>
            </friction>
            <bounce/>
          </surface>
        </collision>
        <collision name='base_link_collision_3'>
          <pose>0 -0.132 -.2195 0 0 0</pose>
          <geometry>
            <box>
              <size>0.25 0.015 0.015</size>
            </box>
          </geometry>
          <surface>
            <contact>
              <ode>
                <min_depth>0.001</min_depth>
                <max_vel>0</max_vel>
              </ode>
            </contact>
            <friction>
              <ode/>
            </friction>
            <bounce/>
          </surface>
        </collision>
        <collision name='base_link_collision_4'>
          <pose>0 0.132 -.2195 0 0 0</pose>
          <geometry>
            <box>
              <size>0.25 0.015 0.015</size>
            </box>
          </geometry>
          <surface>
            <contact>
              <ode>
                <min_depth>0.001</min_depth>
                <max_vel>0</max_vel>
              </ode>
            </contact>
            <friction>
              <ode/>
            </friction>
            <bounce/>
          </surface>
        </collision>
        <sensor name='air_pressure_sensor' type='air_pressure'>
          <pose>0 0 0 0 -0 0</pose>
          <topic>__default__</topic>
          <update_rate>50</update_rate>
          <enable_metrics>false</enable_metrics>
          <air_pressure>
            <reference_altitude>0</reference_altitude>
            <pressure>
              <noise type='gaussian'>
                <mean>0</mean>
                <stddev>0.01</stddev>
                <bias_mean>0</bias_mean>
                <bias_stddev>0</bias_stddev>
                <dynamic_bias_stddev>0</dynamic_bias_stddev>
                <dynamic_bias_correlation_time>0</dynamic_bias_correlation_time>
                <precision>0</precision>
              </noise>
            </pressure>
          </air_pressure>
        </sensor>
        <sensor name='imu_sensor' type='imu'>
          <pose>0 0 0 0 -0 0</pose>
          <topic>__default__</topic>
          <update_rate>250</update_rate>
          <enable_metrics>false</enable_metrics>
          <imu>
            <orientation_reference_frame>
              <localization>CUSTOM</localization>
              <custom_rpy>0 0 0</custom_rpy>
              <grav_dir_x>1 0 0</grav_dir_x>
            </orientation_reference_frame>
            <angular_velocity>
              <x>
                <noise type='gaussian'>
                  <mean>0</mean>
                  <stddev>0.00018665000000000001</stddev>
                  <bias_mean>0</bias_mean>
                  <bias_stddev>0</bias_stddev>
                  <dynamic_bias_stddev>3.8785000000000002e-05</dynamic_bias_stddev>
                  <dynamic_bias_correlation_time>1000</dynamic_bias_correlation_time>
                  <precision>0</precision>
                </noise>
              </x>
              <y>
                <noise type='gaussian'>
                  <mean>0</mean>
                  <stddev>0.00018665000000000001</stddev>
                  <bias_mean>0</bias_mean>
                  <bias_stddev>0</bias_stddev>
                  <dynamic_bias_stddev>3.8785000000000002e-05</dynamic_bias_stddev>
                  <dynamic_bias_correlation_time>1000</dynamic_bias_correlation_time>
                  <precision>0</precision>
                </noise>
              </y>
              <z>
                <noise type='gaussian'>
                  <mean>0</mean>
                  <stddev>0.00018665000000000001</stddev>
                  <bias_mean>0</bias_mean>
                  <bias_stddev>0</bias_stddev>
                  <dynamic_bias_stddev>3.8785000000000002e-05</dynamic_bias_stddev>
                  <dynamic_bias_correlation_time>1000</dynamic_bias_correlation_time>
                  <precision>0</precision>
                </noise>
              </z>
            </angular_velocity>
            <linear_acceleration>
              <x>
                <noise type='gaussian'>
                  <mean>0</mean>
                  <stddev>0.0018600000000000001</stddev>
                  <bias_mean>0</bias_mean>
                  <bias_stddev>0</bias_stddev>
                  <dynamic_bias_stddev>0.0060000000000000001</dynamic_bias_stddev>
                  <dynamic_bias_correlation_time>300</dynamic_bias_correlation_time>
                  <precision>0</precision>
                </noise>
              </x>
              <y>
                <noise type='gaussian'>
                  <mean>0</mean>
                  <stddev>0.0018600000000000001</stddev>
                  <bias_mean>0</bias_mean>
                  <bias_stddev>0</bias_stddev>
                  <dynamic_bias_stddev>0.0060000000000000001</dynamic_bias_stddev>
                  <dynamic_bias_correlation_time>300</dynamic_bias_correlation_time>
                  <precision>0</precision>
                </noise>
              </y>
              <z>
                <noise type='gaussian'>
                  <mean>0</mean>
                  <stddev>0.0018600000000000001</stddev>
                  <bias_mean>0</bias_mean>
                  <bias_stddev>0</bias_stddev>
                  <dynamic_bias_stddev>0.0060000000000000001</dynamic_bias_stddev>
                  <dynamic_bias_correlation_time>300</dynamic_bias_correlation_time>
                  <precision>0</precision>
                </noise>
              </z>
            </linear_acceleration>
            <enable_orientation>true</enable_orientation>
          </imu>
        </sensor>
        <sensor name='navsat_sensor' type='navsat'>
          <always_on>true</always_on>
          <update_rate>30</update_rate>
          <gps/>
        </sensor>
        <pose>0 0 0 0 -0 0</pose>
        <enable_wind>true</enable_wind>
      </link>
      <link name='rotor_0'>
        <gravity>true</gravity>
        <self_collide>false</self_collide>
        <velocity_decay/>
        <pose>0.174 -0.174 0.06 0 -0 0</pose>
        <inertial>
          <mass>0.016076900000000002</mass>
          <inertia>
            <ixx>3.8464900000000002e-07</ixx>
            <iyy>2.6115899999999998e-05</iyy>
            <izz>2.6498600000000001e-05</izz>
            <ixy>0</ixy>
            <ixz>0</ixz>
            <iyz>0</iyz>
          </inertia>
          <pose>0 0 0 0 -0 0</pose>
        </inertial>
        <visual name='rotor_0_visual'>
          <pose>-0.022 -0.14638461538461536 -0.016 0 0 0</pose>
          <geometry>
            <mesh>
              <scale>0.846154 0.846154 0.846154</scale>
              <uri>https://fuel.gazebosim.org/1.0/px4/models/x500_base/1/files/meshes/1345_prop_ccw.stl</uri>
            </mesh>
          </geometry>
          <material>
            <script>
              <name>Gazebo/DarkGrey</name>
              <uri>file://media/materials/scripts/gazebo.material</uri>
            </script>
          </material>
        </visual>
        <visual name='rotor_0_visual_motor_bell'>
          <pose>0 0 -.032 0 0 0</pose>
          <geometry>
            <mesh>
              <scale>1 1 1</scale>
              <uri>https://fuel.gazebosim.org/1.0/px4/models/x500_base/1/files/meshes/5010Bell.dae</uri>
            </mesh>
          </geometry>
        </visual>
        <collision name='rotor_0_collision'>
          <pose>0 0 0 0 0 0</pose>
          <geometry>
            <box>
              <size>0.279231 0.016923 0.000846</size>
            </box>
          </geometry>
          <surface>
            <contact>
              <ode>
                <min_depth>0.001</min_depth>
                <max_vel>0</max_vel>
              </ode>
            </contact>
            <friction>
              <ode/>
            </friction>
            <bounce/>
          </surface>
        </collision>
        <enable_wind>true</enable_wind>
      </link>
      <joint name='rotor_0_joint' type='revolute'>
        <parent>base_link</parent>
        <child>rotor_0</child>
        <axis>
          <xyz>0 0 1</xyz>
          <limit>
            <lower>-10000000000000000</lower>
            <upper>10000000000000000</upper>
            <effort>inf</effort>
            <velocity>inf</velocity>
            <stiffness>100000000</stiffness>
            <dissipation>1</dissipation>
          </limit>
          <dynamics>
            <spring_reference>0</spring_reference>
            <spring_stiffness>0</spring_stiffness>
            <damping>0</damping>
            <friction>0</friction>
          </dynamics>
        </axis>
        <pose>0 0 0 0 -0 0</pose>
      </joint>
      <link name='rotor_1'>
        <gravity>true</gravity>
        <self_collide>false</self_collide>
        <velocity_decay/>
        <pose>-0.174 0.174 0.06 0 -0 0</pose>
        <inertial>
          <mass>0.016076900000000002</mass>
          <inertia>
            <ixx>3.8464900000000002e-07</ixx>
            <iyy>2.6115899999999998e-05</iyy>
            <izz>2.6498600000000001e-05</izz>
            <ixy>0</ixy>
            <ixz>0</ixz>
            <iyz>0</iyz>
          </inertia>
          <pose>0 0 0 0 -0 0</pose>
        </inertial>
        <visual name='rotor_1_visual'>
          <pose>-0.022 -0.14638461538461536 -0.016 0 0 0</pose>
          <geometry>
            <mesh>
              <scale>0.846154 0.846154 0.846154</scale>
              <uri>https://fuel.gazebosim.org/1.0/px4/models/x500_base/1/files/meshes/1345_prop_ccw.stl</uri>
            </mesh>
          </geometry>
          <material>
            <script>
              <name>Gazebo/DarkGrey</name>
              <uri>file://media/materials/scripts/gazebo.material</uri>
            </script>
          </material>
        </visual>
        <visual name='rotor_1_visual_motor_top'>
          <pose>0 0 -.032 0 0 0</pose>
          <geometry>
            <mesh>
              <scale>1 1 1</scale>
              <uri>https://fuel.gazebosim.org/1.0/px4/models/x500_base/1/files/meshes/5010Bell.dae</uri>
            </mesh>
          </geometry>
        </visual>
        <collision name='rotor_1_collision'>
          <pose>0 0 0 0 0 0</pose>
          <geometry>
            <box>
              <size>0.279231 0.016923 0.000846</size>
            </box>
          </geometry>
          <surface>
            <contact>
              <ode>
                <min_depth>0.001</min_depth>
                <max_vel>0</max_vel>
              </ode>
            </contact>
            <friction>
              <ode/>
            </friction>
            <bounce/>
          </surface>
        </collision>
        <enable_wind>true</enable_wind>
      </link>
      <joint name='rotor_1_joint' type='revolute'>
        <parent>base_link</parent>
        <child>rotor_1</child>
        <axis>
          <xyz>0 0 1</xyz>
          <limit>
            <lower>-10000000000000000</lower>
            <upper>10000000000000000</upper>
            <effort>inf</effort>
            <velocity>inf</velocity>
            <stiffness>100000000</stiffness>
            <dissipation>1</dissipation>
          </limit>
          <dynamics>
            <spring_reference>0</spring_reference>
            <spring_stiffness>0</spring_stiffness>
            <damping>0</damping>
            <friction>0</friction>
          </dynamics>
        </axis>
        <pose>0 0 0 0 -0 0</pose>
      </joint>
      <link name='rotor_2'>
        <gravity>true</gravity>
        <self_collide>false</self_collide>
        <velocity_decay/>
        <pose>0.174 0.174 0.06 0 -0 0</pose>
        <inertial>
          <mass>0.016076900000000002</mass>
          <inertia>
            <ixx>3.8464900000000002e-07</ixx>
            <iyy>2.6115899999999998e-05</iyy>
            <izz>2.6498600000000001e-05</izz>
            <ixy>0</ixy>
            <ixz>0</ixz>
            <iyz>0</iyz>
          </inertia>
          <pose>0 0 0 0 -0 0</pose>
        </inertial>
        <visual name='rotor_2_visual'>
          <pose>-0.022 -0.14638461538461536 -0.016 0 0 0</pose>
          <geometry>
            <mesh>
              <scale>0.846154 0.846154 0.846154</scale>
              <uri>https://fuel.gazebosim.org/1.0/px4/models/x500_base/1/files/meshes/1345_prop_cw.stl</uri>
            </mesh>
          </geometry>
          <material>
            <script>
              <name>Gazebo/DarkGrey</name>
              <uri>file://media/materials/scripts/gazebo.material</uri>
            </script>
          </material>
        </visual>
        <visual name='rotor_2_visual_motor_top'>
          <pose>0 0 -.032 0 0 0</pose>
          <geometry>
            <mesh>
              <scale>1 1 1</scale>
              <uri>https://fuel.gazebosim.org/1.0/px4/models/x500_base/1/files/meshes/5010Bell.dae</uri>
            </mesh>
          </geometry>
        </visual>
        <collision name='rotor_2_collision'>
          <pose>0 0 0 0 0 0</pose>
          <geometry>
            <box>
              <size>0.279231 0.016923 0.000846</size>
            </box>
          </geometry>
          <surface>
            <contact>
              <ode>
                <min_depth>0.001</min_depth>
                <max_vel>0</max_vel>
              </ode>
            </contact>
            <friction>
              <ode/>
            </friction>
            <bounce/>
          </surface>
        </collision>
        <enable_wind>true</enable_wind>
      </link>
      <joint name='rotor_2_joint' type='revolute'>
        <parent>base_link</parent>
        <child>rotor_2</child>
        <axis>
          <xyz>0 0 1</xyz>
          <limit>
            <lower>-10000000000000000</lower>
            <upper>10000000000000000</upper>
            <effort>inf</effort>
            <velocity>inf</velocity>
            <stiffness>100000000</stiffness>
            <dissipation>1</dissipation>
          </limit>
          <dynamics>
            <spring_reference>0</spring_reference>
            <spring_stiffness>0</spring_stiffness>
            <damping>0</damping>
            <friction>0</friction>
          </dynamics>
        </axis>
        <pose>0 0 0 0 -0 0</pose>
      </joint>
      <link name='rotor_3'>
        <gravity>true</gravity>
        <self_collide>false</self_collide>
        <velocity_decay/>
        <pose>-0.174 -0.174 0.06 0 -0 0</pose>
        <inertial>
          <mass>0.016076900000000002</mass>
          <inertia>
            <ixx>3.8464900000000002e-07</ixx>
            <iyy>2.6115899999999998e-05</iyy>
            <izz>2.6498600000000001e-05</izz>
            <ixy>0</ixy>
            <ixz>0</ixz>
            <iyz>0</iyz>
          </inertia>
          <pose>0 0 0 0 -0 0</pose>
        </inertial>
        <visual name='rotor_3_visual'>
          <pose>-0.022 -0.14638461538461536 -0.016 0 0 0</pose>
          <geometry>
            <mesh>
              <scale>0.846154 0.846154 0.846154</scale>
              <uri>https://fuel.gazebosim.org/1.0/px4/models/x500_base/1/files/meshes/1345_prop_cw.stl</uri>
            </mesh>
          </geometry>
          <material>
            <script>
              <name>Gazebo/DarkGrey</name>
              <uri>file://media/materials/scripts/gazebo.material</uri>
            </script>
          </material>
        </visual>
        <visual name='rotor_3_visual_motor_top'>
          <pose>0 0 -.032 0 0 0</pose>
          <geometry>
            <mesh>
              <scale>1 1 1</scale>
              <uri>https://fuel.gazebosim.org/1.0/px4/models/x500_base/1/files/meshes/5010Bell.dae</uri>
            </mesh>
          </geometry>
        </visual>
        <collision name='rotor_3_collision'>
          <pose>0 0 0 0 0 0</pose>
          <geometry>
            <box>
              <size>0.279231 0.016923 0.000846</size>
            </box>
          </geometry>
          <surface>
            <contact>
              <ode>
                <min_depth>0.001</min_depth>
                <max_vel>0</max_vel>
              </ode>
            </contact>
            <friction>
              <ode/>
            </friction>
            <bounce/>
          </surface>
        </collision>
              
      </link>
      <joint name='rotor_3_joint' type='revolute'>
        <parent>base_link</parent>
        <child>rotor_3</child>
        <axis>
          <xyz>0 0 1</xyz>
          <limit>
            <lower>-10000000000000000</lower>
            <upper>10000000000000000</upper>
            <effort>inf</effort>
            <velocity>inf</velocity>
            <stiffness>100000000</stiffness>
            <dissipation>1</dissipation>
          </limit>
          <dynamics>
            <spring_reference>0</spring_reference>
            <spring_stiffness>0</spring_stiffness>
            <damping>0</damping>
            <friction>0</friction>
          </dynamics>
        </axis>
        <pose>0 0 0 0 -0 0</pose>
      </joint>
    </model>


</sdf>